Workbook
Name ALOS_Factor_Options: 'M2 BOR & Tradeoff analysis'!$N$20:$N$24
Name Average_ALOS_Options: 'M2 BOR & Tradeoff analysis'!$N$8:$N$12
Name Bed_Expansion_Rate_Options: 'M2 BOR & Tradeoff analysis'!$N$3:$N$6
Name Elderly_Population_Growth_Adjust_Options: 'M2 BOR & Tradeoff analysis'!$N$14:$N$18
Name Govt_Policy_Factor_Options: 'M2 BOR & Tradeoff analysis'!$N$26:$N$27

Sheet Overview
B1: Singapore Public Healthcare Sustainability 2026–2035 | L1: IS 602 · G2 Group 6
B2: Motivation: Singapore is ageing fast, 1 in 4 Singaporeans aged 65+ by 2030 Rising healthcare demand and increased costs. Can Singapore's public healthcare system remain sustainable through 2035 and what will affect it?
B3: Our approach: A 4-module spreadsheet model covering demographics, hospital capacity, healthcare costs and financing sustainability
A4: Prepared by: Akshaya Vijayakumar Sivakami · Carina Faith Peh Xin Yi · Cher In Teo · Serene Cheng · Xiong Yu
B5: KEY METRICS AT A GLANCE by 2035
B6: Elderly Dependency Ratio Aged 65 and above | E6: Bed Occupancy Rate | H6: Projected Government Healthcare Cost | K6: Financing Deficit
B7: ='M1 Demand Driver'!AF30/100 -> 0.4094669 | E7: ='M2 BOR & Tradeoff analysis'!G37 -> 0.74213922 | H7: SGD Billion | I7: ='M3 Healthcare Costs'!K19 -> 14104.814 | K7: SGD Billion | L7: ='M4 Financing Gap and OOP'!P26 -> 951.47416
B8: significant increase from 11% in 2005 KEY DEMAND DRIVER | E8: within 85% threshold | H8: up from SGD 7.5B in 2025 | K8: deficit from 2031 — 8.6% of budget
B10: NAVIGATION (Click on sheet name to enter)
B11: SHEET NAME | E11: DESCRIPTION
B12: Influence Diagram | E12: Visual map of how all model variables connect and interact across modules
B13: Blackbox | E13: Full model overview — inputs, processes and outputs
B14: M1 Population | E14: Mortality & fertility rates projections 2026–2035
B15: M1 Demand Driver | E15: Projected age-band population and elderly dependency ratio
B16: M2 HAR | E16: Age-specific hospital admission rates used to forecast bed demand
B17: M2 Beds | E17: Annual acute bed expansion projections
B18: M2 BOR & Tradeoff Analysis | E18: Projected Bed Occupancy Rate (BOR)
B19: M2 Sensitivity Analysis | E19: Sensitivity analysis: impact of expansion rate, ALOS & policy factors on BOR
B20: M3 Healthcare Budget | E20: Government healthcare operating expenditure projections 2026–2035
B21: M3 Healthcare Costs | E21: Cost per admission for government and total projected healthcare expenditure with medical inflation
B22: M3 Sensitivity Analysis | E22: One-way and two-way sensitivity: inflation rate vs elderly cost multiplier
... B27: Data | E27: Source datasets

Sheet Influence Diagram
A1: Influence Diagram
A21: Legend

Sheet Blackbox
A1: Blackbox
A3: Input | K3: Output
A5: Decisions (Controllable) | K5: Performance measures
A6: Beds in public acute hospital | K6: Financing gap (surplus or deficit)
A7: Weighted avg govt subsidy rate | K7: Healthcare as % of household income (Burden status)
A8: Government operating healthcare expenditure
A9: Acute inpatient subsidies
A11: Parameters (Uncontrollable) | K11: Consequence variables
A12: Age-specific fertility rates | K12: Projected govt funded annual hospital costs
A13: Age-specific mortality rates | K13: Total out of pocket expenditure
A14: Hospital admission rate | K14: Govt operating expenditure on hospital budget
A15: Medical inflation rate | K15: Total hospital bed-day demand
A16: Healthcare CPI | K16: Bed Occupancy Rate
A17: Annual household income
A18: No. of residents household

Sheet M1 Population
A1: Average Mortality and Survival Rates (based on rates fom 2021 - 2025) | E1: Age-specific Fertility Rates (per thousand residents) Projected (using rates from 2015 - 2025)
A2: Data Series | B2: Avg Mortality Rate | C2: Avg Survival Rate
A3: Under 1 Year | B3: =AVERAGE($R52:$V52) -> 2.02 | C3: =1-(B3/1000) -> 0.99798 | E3: Data Series | F3: 2026 | G3: 2027 | H3: 2028 | I3: 2029 | J3: 2030 | K3: 2031 | L3: 2032 | M3: 2033 | N3: 2034 | O3: 2035
A4: 1 - 4 Years | B4: =AVERAGE($R53:$V53) -> 0.1 | C4: =1-(B4/1000) -> 0.9999 | E4: 15 - 19 Years | F4: {=GROWTH($P14:$Z14, $P$13:$Z$13, F$3)} -> 1.7031888 | G4: {=GROWTH($P14:$Z14, $P$13:$Z$13, G$3)} -> 1.6234625 | H4: {=GROWTH($P14:$Z14, $P$13:$Z$13, H$3)} -> 1.5474683 | I4: {=GROWTH($P14:$Z14, $P$13:$Z$13, I$3)} -> 1.4750313 | J4: {=GROWTH($P14:$Z14, $P$13:$Z$13, J$3)} -> 1.4059851 | K4: {=GROWTH($P14:$Z14, $P$13:$Z$13, K$3)} -> 1.340171 | L4: {=GROWTH($P14:$Z14, $P$13:$Z$13, L$3)} -> 1.2774376 | M4: {=GROWTH($P14:$Z14, $P$13:$Z$13, M$3)} -> 1.2176408 | ... O4: {=GROWTH($P14:$Z14, $P$13:$Z$13, O$3)} -> 1.1063134
A5: 5 - 9 Years | B5: =AVERAGE($R54:$V54) -> 0.1 | C5: =1-(B5/1000) -> 0.9999 | E5: 20 - 24 Years | F5: {=GROWTH($P15:$Z15, $P$13:$Z$13, F$3)} -> 8.3187496 | G5: {=GROWTH($P15:$Z15, $P$13:$Z$13, G$3)} -> 7.7580791 | H5: {=GROWTH($P15:$Z15, $P$13:$Z$13, H$3)} -> 7.2351969 | I5: {=GROWTH($P15:$Z15, $P$13:$Z$13, I$3)} -> 6.7475562 | J5: {=GROWTH($P15:$Z15, $P$13:$Z$13, J$3)} -> 6.2927817 | K5: {=GROWTH($P15:$Z15, $P$13:$Z$13, K$3)} -> 5.8686582 | L5: {=GROWTH($P15:$Z15, $P$13:$Z$13, L$3)} -> 5.47312 | M5: {=GROWTH($P15:$Z15, $P$13:$Z$13, M$3)} -> 5.1042404 | ... O5: {=GROWTH($P15:$Z15, $P$13:$Z$13, O$3)} -> 4.4393913
A6: 10 - 14 Years | B6: =AVERAGE($R55:$V55) -> 0.12 | C6: =1-(B6/1000) -> 0.99988 | E6: 25 - 29 Years | F6: {=GROWTH($P16:$Z16, $P$13:$Z$13, F$3)} -> 38.022728 | G6: {=GROWTH($P16:$Z16, $P$13:$Z$13, G$3)} -> 35.919573 | H6: {=GROWTH($P16:$Z16, $P$13:$Z$13, H$3)} -> 33.932749 | I6: {=GROWTH($P16:$Z16, $P$13:$Z$13, I$3)} -> 32.055823 | J6: {=GROWTH($P16:$Z16, $P$13:$Z$13, J$3)} -> 30.282716 | K6: {=GROWTH($P16:$Z16, $P$13:$Z$13, K$3)} -> 28.607684 | L6: {=GROWTH($P16:$Z16, $P$13:$Z$13, L$3)} -> 27.025304 | M6: {=GROWTH($P16:$Z16, $P$13:$Z$13, M$3)} -> 25.53045 | ... O6: {=GROWTH($P16:$Z16, $P$13:$Z$13, O$3)} -> 22.784224
A7: 15 - 19 Years | B7: =AVERAGE($R56:$V56) -> 0.22 | C7: =1-(B7/1000) -> 0.99978 | E7: 30 - 34 Years | F7: {=GROWTH($P17:$Z17, $P$13:$Z$13, F$3)} -> 74.141049 | G7: {=GROWTH($P17:$Z17, $P$13:$Z$13, G$3)} -> 72.065164 | H7: {=GROWTH($P17:$Z17, $P$13:$Z$13, H$3)} -> 70.047401 | I7: {=GROWTH($P17:$Z17, $P$13:$Z$13, I$3)} -> 68.086134 | J7: {=GROWTH($P17:$Z17, $P$13:$Z$13, J$3)} -> 66.17978 | K7: {=GROWTH($P17:$Z17, $P$13:$Z$13, K$3)} -> 64.326803 | L7: {=GROWTH($P17:$Z17, $P$13:$Z$13, L$3)} -> 62.525708 | M7: {=GROWTH($P17:$Z17, $P$13:$Z$13, M$3)} -> 60.775042 | ... O7: {=GROWTH($P17:$Z17, $P$13:$Z$13, O$3)} -> 57.419388
A8: 20 - 24 Years | B8: =AVERAGE($R57:$V57) -> 0.24 | C8: =1-(B8/1000) -> 0.99976 | E8: 35 - 39 Years | F8: {=GROWTH($P18:$Z18, $P$13:$Z$13, F$3)} -> 48.525004 | G8: {=GROWTH($P18:$Z18, $P$13:$Z$13, G$3)} -> 48.394502 | H8: {=GROWTH($P18:$Z18, $P$13:$Z$13, H$3)} -> 48.264352 | I8: {=GROWTH($P18:$Z18, $P$13:$Z$13, I$3)} -> 48.134552 | J8: {=GROWTH($P18:$Z18, $P$13:$Z$13, J$3)} -> 48.0051 | K8: {=GROWTH($P18:$Z18, $P$13:$Z$13, K$3)} -> 47.875997 | L8: {=GROWTH($P18:$Z18, $P$13:$Z$13, L$3)} -> 47.747241 | M8: {=GROWTH($P18:$Z18, $P$13:$Z$13, M$3)} -> 47.618831 | ... O8: {=GROWTH($P18:$Z18, $P$13:$Z$13, O$3)} -> 47.363047
A9: 25 - 29 Years | B9: =AVERAGE($R58:$V58) -> 0.3 | C9: =1-(B9/1000) -> 0.9997 | E9: 40 - 44 Years | F9: {=GROWTH($P19:$Z19, $P$13:$Z$13, F$3)} -> 10.223882 | G9: {=GROWTH($P19:$Z19, $P$13:$Z$13, G$3)} -> 10.355573 | H9: {=GROWTH($P19:$Z19, $P$13:$Z$13, H$3)} -> 10.48896 | I9: {=GROWTH($P19:$Z19, $P$13:$Z$13, I$3)} -> 10.624066 | J9: {=GROWTH($P19:$Z19, $P$13:$Z$13, J$3)} -> 10.760911 | K9: {=GROWTH($P19:$Z19, $P$13:$Z$13, K$3)} -> 10.89952 | L9: {=GROWTH($P19:$Z19, $P$13:$Z$13, L$3)} -> 11.039914 | M9: {=GROWTH($P19:$Z19, $P$13:$Z$13, M$3)} -> 11.182116 | ... O9: {=GROWTH($P19:$Z19, $P$13:$Z$13, O$3)} -> 11.472039
A10: 30 - 34 Years | B10: =AVERAGE($R59:$V59) -> 0.36 | C10: =1-(B10/1000) -> 0.99964 | E10: 45 - 49 Years | F10: {=GROWTH($P20:$Z20, $P$13:$Z$13, F$3)} -> 0.56881686 | G10: {=GROWTH($P20:$Z20, $P$13:$Z$13, G$3)} -> 0.59158904 | H10: {=GROWTH($P20:$Z20, $P$13:$Z$13, H$3)} -> 0.61527288 | I10: {=GROWTH($P20:$Z20, $P$13:$Z$13, I$3)} -> 0.63990489 | J10: {=GROWTH($P20:$Z20, $P$13:$Z$13, J$3)} -> 0.66552303 | K10: {=GROWTH($P20:$Z20, $P$13:$Z$13, K$3)} -> 0.69216677 | L10: {=GROWTH($P20:$Z20, $P$13:$Z$13, L$3)} -> 0.71987717 | M10: {=GROWTH($P20:$Z20, $P$13:$Z$13, M$3)} -> 0.74869694 | ... O10: {=GROWTH($P20:$Z20, $P$13:$Z$13, O$3)} -> 0.809844
A11: 35 - 39 Years | B11: =AVERAGE($R60:$V60) -> 0.52 | C11: =1-(B11/1000) -> 0.99948
A12: 40 - 44 Years | B12: =AVERAGE($R61:$V61) -> 0.8 | C12: =1-(B12/1000) -> 0.9992 | E12: Fertility Rates from 2005 to 2025
A13: 45 - 49 Years | B13: =AVERAGE($R62:$V62) -> 1.34 | C13: =1-(B13/1000) -> 0.99866 | E13: Data Series | F13: 2005 | G13: 2006 | H13: 2007 | I13: 2008 | J13: 2009 | K13: 2010 | L13: 2011 | M13: 2012 | N13: 2013 | O13: 2014 | P13: 2015 | Q13: 2016 | R13: 2017 | S13: 2018 | T13: 2019 | U13: 2020 | V13: 2021 | W13: 2022 | X13: 2023 | Y13: 2024 | Z13: 2025
A14: 50 - 54 Years | B14: =AVERAGE($R63:$V63) -> 2.22 | C14: =1-(B14/1000) -> 0.99778 | E14: 15 - 19 Years | F14: 7.2 | G14: 6.6 | H14: 6.1 | I14: 6.1 | J14: 5 | K14: 4.8 | L14: 4.7 | M14: 4.3 | N14: 3.8 | O14: 3.3 | P14: 2.7 | Q14: 2.7 | R14: 2.6 | S14: 2.5 | T14: 2.5 | U14: 2.3 | V14: 2.2 | W14: 2.1 | X14: 2.2 | Y14: 2.3 | Z14: 1.3
A15: 55 - 59 Years | B15: =AVERAGE($R64:$V64) -> 3.58 | C15: =1-(B15/1000) -> 0.99642 | E15: 20 - 24 Years | F15: 32.5 | G15: 30.6 | H15: 31.2 | I15: 29.1 | J15: 25.4 | K15: 23.3 | L15: 22.4 | M15: 22.2 | N15: 19.7 | O15: 19.5 | P15: 18.7 | Q15: 17 | R15: 15.1 | S15: 14.4 | T15: 12.7 | U15: 12.7 | V15: 11.7 | W15: 11.2 | X15: 10.6 | Y15: 9.8 | Z15: 8.7
A16: 60 - 64 Years | B16: =AVERAGE($R65:$V65) -> 5.96 | C16: =1-(B16/1000) -> 0.99404 | E16: 25 - 29 Years | F16: 80.7 | G16: 79.6 | H16: 78.7 | I16: 78.9 | J16: 74.2 | K16: 68.1 | L16: 73.4 | M16: 76.7 | N16: 70.5 | O16: 71.1 | P16: 68.7 | Q16: 65.8 | R16: 62.2 | S16: 60.6 | T16: 59.4 | U16: 54.6 | V16: 53.4 | W16: 48.8 | X16: 43.7 | Y16: 42.6 | Z16: 38.3
A17: 65 - 69 Years | B17: =AVERAGE($R66:$V66) -> 9.62 | C17: =1-(B17/1000) -> 0.99038 | E17: 30 - 34 Years | F17: 89.2 | G17: 93.1 | H17: 94.4 | I17: 94.6 | J17: 90.1 | K17: 86 | L17: 89.5 | M17: 99.5 | N17: 90.2 | O17: 99.3 | P17: 98.5 | Q17: 96.2 | R17: 93.3 | S17: 92.9 | T17: 92.4 | U17: 90.8 | V17: 92.9 | W17: 86.7 | X17: 78.7 | Y17: 79.3 | Z17: 70
A18: 70 - 74 Years | B18: =AVERAGE($R67:$V67) -> 15.34 | C18: =1-(B18/1000) -> 0.98466 | E18: 35 - 39 Years | F18: 36.8 | G18: 38.7 | H18: 41.5 | I18: 41.5 | J18: 42.6 | K18: 42.2 | L18: 42.4 | M18: 46.3 | N18: 44.7 | O18: 48.3 | P18: 49.9 | Q18: 49.7 | R18: 48.6 | S18: 48.4 | T18: 50.1 | U18: 49 | V18: 53.6 | W18: 49.4 | X18: 47.9 | Y18: 50 | Z18: 46.2
A19: 75 - 79 Years | B19: =AVERAGE($R68:$V68) -> 26.66 | C19: =1-(B19/1000) -> 0.97334 | E19: 40 - 44 Years | F19: 6.2 | G19: 6.4 | H19: 6.4 | I19: 6.6 | J19: 7 | K19: 6.1 | L19: 7.2 | M19: 8 | N19: 8 | O19: 8.3 | P19: 8.9 | Q19: 8.8 | R19: 9 | S19: 8.8 | T19: 9.9 | U19: 9.5 | V19: 10.2 | W19: 9.8 | X19: 9.6 | Y19: 10.2 | Z19: 9.6
A20: 80 - 84 Years | B20: =AVERAGE($R69:$V69) -> 49.98 | C20: =1-(B20/1000) -> 0.95002 | E20: 45 - 49 Years | F20: 0.2 | G20: 0.2 | H20: 0.2 | I20: 0.2 | J20: 0.3 | K20: 0.3 | L20: 0.3 | M20: 0.3 | N20: 0.3 | O20: 0.3 | P20: 0.4 | Q20: 0.3 | R20: 0.5 | S20: 0.5 | T20: 0.4 | U20: 0.5 | V20: 0.3 | W20: 0.4 | X20: 0.6 | Y20: 0.7 | Z20: 0.5
A21: 85 - 89 Years | B21: =AVERAGE($R70:$V70) -> 91.9 | C21: =1-(B21/1000) -> 0.9081
A22: 90 Years & Over | B22: =AVERAGE($R71:$V71) -> 168.6 | C22: =1-(B22/1000) -> 0.8314
A50: Mortality Rates from 2005 to 2025
A51: Data Series | B51: 2005 | C51: 2006 | D51: 2007 | E51: 2008 | F51: 2009 | G51: 2010 | H51: 2011 | I51: 2012 | J51: 2013 | K51: 2014 | L51: 2015 | M51: 2016 | N51: 2017 | O51: 2018 | P51: 2019 | Q51: 2020 | R51: 2021 | S51: 2022 | T51: 2023 | U51: 2024 | V51: 2025
A52: Under 1 Year | B52: 2.1 | C52: 2.6 | D52: 2.1 | E52: 2.1 | F52: 2.2 | G52: 2 | H52: 2 | I52: 1.8 | J52: 2 | K52: 1.8 | L52: 1.7 | M52: 2.4 | N52: 2.2 | O52: 2.1 | P52: 1.7 | Q52: 1.8 | R52: 1.8 | S52: 1.8 | T52: 2.2 | U52: 2.3 | V52: 2
A53: 1 - 4 Years | B53: 0.2 | C53: 0.1 | D53: 0.1 | E53: 0.2 | F53: 0.2 | G53: 0.1 | H53: 0.2 | I53: 0.2 | J53: 0.2 | K53: 0.1 | L53: 0.1 | M53: 0.1 | N53: 0.1 | O53: 0.1 | P53: 0.1 | Q53: 0.1 | R53: 0.1 | S53: 0.1 | T53: 0.1 | U53: 0.1 | V53: 0.1
A54: 5 - 9 Years | B54: 0.1 | C54: 0.1 | D54: 0.1 | E54: 0.1 | F54: 0.1 | G54: 0.1 | H54: 0.1 | I54: 0.1 | J54: 0.1 | K54: - | L54: - | M54: 0.1 | N54: - | O54: 0.1 | P54: 0.1 | Q54: - | R54: - | S54: 0.1 | T54: 0.1 | U54: 0.1 | V54: 0.1
A55: 10 - 14 Years | B55: 0.1 | C55: 0.2 | D55: 0.1 | E55: 0.1 | F55: 0.1 | G55: 0.1 | H55: 0.1 | I55: 0.1 | J55: 0.1 | K55: - | L55: 0.1 | M55: 0.1 | N55: 0.1 | O55: 0.1 | P55: - | Q55: 0.1 | R55: 0.1 | S55: 0.2 | T55: 0.1 | U55: 0.1 | V55: 0.1
A56: 15 - 19 Years | B56: 0.2 | C56: 0.2 | D56: 0.2 | E56: 0.2 | F56: 0.2 | G56: 0.2 | H56: 0.2 | I56: 0.2 | J56: 0.2 | K56: 0.2 | L56: 0.2 | M56: 0.2 | N56: 0.2 | O56: 0.2 | P56: 0.2 | Q56: 0.2 | R56: 0.3 | S56: 0.2 | T56: 0.2 | U56: 0.2 | V56: 0.2
A57: 20 - 24 Years | B57: 0.4 | C57: 0.4 | D57: 0.4 | E57: 0.4 | F57: 0.4 | G57: 0.3 | H57: 0.3 | I57: 0.3 | J57: 0.3 | K57: 0.3 | L57: 0.2 | M57: 0.2 | N57: 0.2 | O57: 0.3 | P57: 0.3 | Q57: 0.2 | R57: 0.2 | S57: 0.3 | T57: 0.2 | U57: 0.3 | V57: 0.2
A58: 25 - 29 Years | B58: 0.4 | C58: 0.4 | D58: 0.4 | E58: 0.4 | F58: 0.3 | G58: 0.3 | H58: 0.3 | I58: 0.3 | J58: 0.3 | K58: 0.2 | L58: 0.3 | M58: 0.3 | N58: 0.3 | O58: 0.3 | P58: 0.2 | Q58: 0.3 | R58: 0.3 | S58: 0.3 | T58: 0.3 | U58: 0.3 | V58: 0.3
A59: 30 - 34 Years | B59: 0.5 | C59: 0.5 | D59: 0.4 | E59: 0.4 | F59: 0.4 | G59: 0.3 | H59: 0.4 | I59: 0.4 | J59: 0.4 | K59: 0.4 | L59: 0.4 | M59: 0.3 | N59: 0.4 | O59: 0.4 | P59: 0.4 | Q59: 0.3 | R59: 0.3 | S59: 0.4 | T59: 0.3 | U59: 0.4 | V59: 0.4
A60: 35 - 39 Years | B60: 0.8 | C60: 0.7 | D60: 0.6 | E60: 0.7 | F60: 0.6 | G60: 0.6 | H60: 0.5 | I60: 0.6 | J60: 0.5 | K60: 0.5 | L60: 0.5 | M60: 0.5 | N60: 0.5 | O60: 0.5 | P60: 0.5 | Q60: 0.5 | R60: 0.5 | S60: 0.6 | T60: 0.5 | U60: 0.5 | V60: 0.5
A61: 40 - 44 Years | B61: 1.2 | C61: 1.3 | D61: 1.2 | E61: 1.2 | F61: 0.9 | G61: 1 | H61: 0.9 | I61: 0.9 | J61: 0.9 | K61: 0.9 | L61: 0.9 | M61: 0.9 | N61: 0.8 | O61: 0.7 | P61: 0.8 | Q61: 0.8 | R61: 0.8 | S61: 0.8 | T61: 0.8 | U61: 0.8 | V61: 0.8
A62: 45 - 49 Years | B62: 1.9 | C62: 1.9 | D62: 1.9 | E62: 1.8 | F62: 1.6 | G62: 1.7 | H62: 1.7 | I62: 1.6 | J62: 1.5 | K62: 1.5 | L62: 1.5 | M62: 1.4 | N62: 1.4 | O62: 1.4 | P62: 1.3 | Q62: 1.3 | R62: 1.5 | S62: 1.4 | T62: 1.3 | U62: 1.3 | V62: 1.2
A63: 50 - 54 Years | B63: 3.5 | C63: 3.2 | D63: 3.1 | E63: 3.2 | F63: 3 | G63: 3 | H63: 2.8 | I63: 2.5 | J63: 2.7 | K63: 2.5 | L63: 2.5 | M63: 2.4 | N63: 2.6 | O63: 2.3 | P63: 2.1 | Q63: 2.2 | R63: 2.3 | S63: 2.3 | T63: 2.2 | U63: 2.2 | V63: 2.1
A64: 55 - 59 Years | B64: 5.7 | C64: 5.3 | D64: 5.1 | E64: 5.1 | F64: 4.7 | G64: 4.5 | H64: 4.4 | I64: 4.6 | J64: 4.3 | K64: 4.5 | L64: 4.2 | M64: 4.1 | N64: 3.9 | O64: 3.9 | P64: 3.7 | Q64: 3.7 | R64: 3.8 | S64: 3.6 | T64: 3.7 | U64: 3.5 | V64: 3.3
A65: 60 - 64 Years | B65: 9.3 | C65: 9 | D65: 8.5 | E65: 8.1 | F65: 7.4 | G65: 7.3 | H65: 7 | I65: 7.3 | J65: 7 | K65: 6.4 | L65: 6.5 | M65: 6.2 | N65: 6.3 | O65: 6.3 | P65: 5.9 | Q65: 5.9 | R65: 6.4 | S65: 6.3 | T65: 6 | U65: 5.7 | V65: 5.4
A66: 65 - 69 Years | B66: 16 | C66: 14.1 | D66: 14.1 | E66: 13.9 | F66: 12.8 | G66: 12.5 | H66: 12.6 | I66: 11.9 | J66: 11 | K66: 10.6 | L66: 10.4 | M66: 10.1 | N66: 9.9 | O66: 9.5 | P66: 9 | Q66: 9.2 | R66: 9.7 | S66: 10 | T66: 9.8 | U66: 9.5 | V66: 9.1
A67: 70 - 74 Years | B67: 24.8 | C67: 23.6 | D67: 25.9 | E67: 24.1 | F67: 21.7 | G67: 20.7 | H67: 19.9 | I67: 20 | J67: 19.6 | K67: 18.5 | L67: 18.2 | M67: 16.7 | N67: 16.9 | O67: 16.5 | P67: 15.3 | Q67: 15.1 | R67: 15.8 | S67: 16.2 | T67: 15.4 | U67: 14.9 | V67: 14.4
...

Sheet M1 Demand Driver
A1: Demographic Projection from 2025 - 2035
A3: Age group | B3: 2025 | C3: 2026 | D3: 2027 | E3: 2028 | F3: 2029 | G3: 2030 | H3: 2031 | I3: 2032 | J3: 2033 | K3: 2034 | L3: 2035 | O3: Age Group | P3: 2025 Pop | Q3: Neg 2025 | R3: 2035 Pop
A4: Under 1 Year | B4: ='M1 Population'!V75 -> 29422 | C4: =(SUMPRODUCT($B$8:$B$14,'M1 Population'!F$4:F$10) * 0.5 / 1000) * 'M1 Population'!$C3 -> 27351.397 | D4: =(SUMPRODUCT($B$8:$B$14,'M1 Population'!G$4:G$10) * 0.5 / 1000) * 'M1 Population'!$C3 -> 26676.8 | E4: =(SUMPRODUCT($B$8:$B$14,'M1 Population'!H$4:H$10) * 0.5 / 1000) * 'M1 Population'!$C3 -> 26031.763 | F4: =(SUMPRODUCT($B$8:$B$14,'M1 Population'!I$4:I$10) * 0.5 / 1000) * 'M1 Population'!$C3 -> 25414.892 | G4: =(SUMPRODUCT($B$8:$B$14,'M1 Population'!J$4:J$10) * 0.5 / 1000) * 'M1 Population'!$C3 -> 24824.867 | H4: =(SUMPRODUCT($B$8:$B$14,'M1 Population'!K$4:K$10) * 0.5 / 1000) * 'M1 Population'!$C3 -> 24260.438 | I4: =(SUMPRODUCT($B$8:$B$14,'M1 Population'!L$4:L$10) * 0.5 / 1000) * 'M1 Population'!$C3 -> 23720.419 | J4: =(SUMPRODUCT($B$8:$B$14,'M1 Population'!M$4:M$10) * 0.5 / 1000) * 'M1 Population'!$C3 -> 23203.691 | ... L4: =(SUMPRODUCT($B$8:$B$14,'M1 Population'!O$4:O$10) * 0.5 / 1000) * 'M1 Population'!$C3 -> 22235.906 | O4: Under 1 Year | P4: =B4 -> 29422 | Q4: =-1*P4 -> -29422 | R4: =L4 -> 22235.906
A5: 1 - 4 Years | B5: ='M1 Population'!V76 -> 136128 | C5: =(B4*'M1 Population'!$C$3) + (B5 * 0.8 * 'M1 Population'!$C$4) -> 138254.08 | D5: =(C4*'M1 Population'!$C$3) + (C5 * 0.8 * 'M1 Population'!$C$4) -> 137888.35 | E5: =(D4*'M1 Population'!$C$3) + (D5 * 0.8 * 'M1 Population'!$C$4) -> 136922.56 | F5: =(E4*'M1 Population'!$C$3) + (E5 * 0.8 * 'M1 Population'!$C$4) -> 135506.27 | G5: =(F4*'M1 Population'!$C$3) + (F5 * 0.8 * 'M1 Population'!$C$4) -> 133757.73 | H5: =(G4*'M1 Population'!$C$3) + (G5 * 0.8 * 'M1 Population'!$C$4) -> 131770.21 | I5: =(H4*'M1 Population'!$C$3) + (H5 * 0.8 * 'M1 Population'!$C$4) -> 129617.05 | J5: =(I4*'M1 Population'!$C$3) + (I5 * 0.8 * 'M1 Population'!$C$4) -> 127355.78 | ... L5: =(K4*'M1 Population'!$C$3) + (K5 * 0.8 * 'M1 Population'!$C$4) -> 122678.32 | O5: 1 - 4 Years | P5: =B5 -> 136128 | Q5: =-1*P5 -> -136128 | R5: =L5 -> 122678.32
A6: 5 - 9 Years | B6: ='M1 Population'!V77 -> 199813 | C6: =(B5 * 0.2 * 'M1 Population'!$C$4) +(B6 * 0.8 * 'M1 Population'!$C$5) -> 187057.29 | D6: =(C5 * 0.2 * 'M1 Population'!$C$4) +(C6 * 0.8 * 'M1 Population'!$C$5) -> 177278.92 | E6: =(D5 * 0.2 * 'M1 Population'!$C$4) +(D6 * 0.8 * 'M1 Population'!$C$5) -> 169383.87 | F6: =(E5 * 0.2 * 'M1 Population'!$C$4) +(E6 * 0.8 * 'M1 Population'!$C$5) -> 162875.32 | G6: =(F5 * 0.2 * 'M1 Population'!$C$4) +(F6 * 0.8 * 'M1 Population'!$C$5) -> 157385.77 | H6: =(G5 * 0.2 * 'M1 Population'!$C$4) +(G6 * 0.8 * 'M1 Population'!$C$5) -> 152644.89 | I6: =(H5 * 0.2 * 'M1 Population'!$C$4) +(H6 * 0.8 * 'M1 Population'!$C$5) -> 148455.11 | J6: =(I5 * 0.2 * 'M1 Population'!$C$4) +(I6 * 0.8 * 'M1 Population'!$C$5) -> 144673.03 | ... L6: =(K5 * 0.2 * 'M1 Population'!$C$4) +(K6 * 0.8 * 'M1 Population'!$C$5) -> 137948.82 | O6: 5 - 9 Years | P6: =B6 -> 199813 | Q6: =-1*P6 -> -199813 | R6: =L6 -> 137948.82
A7: 10 - 14 Years | B7: ='M1 Population'!V78 -> 206577 | C7: =(B6 * 0.2 * 'M1 Population'!$C5) + (B7 * 0.8 * 'M1 Population'!$C6) -> 205200.37 | D7: =(C6 * 0.2 * 'M1 Population'!$C5) + (C7 * 0.8 * 'M1 Population'!$C6) -> 201548.32 | E7: =(D6 * 0.2 * 'M1 Population'!$C5) + (D7 * 0.8 * 'M1 Population'!$C6) -> 196671.54 | F7: =(E6 * 0.2 * 'M1 Population'!$C5) + (E7 * 0.8 * 'M1 Population'!$C6) -> 191191.74 | G7: =(F6 * 0.2 * 'M1 Population'!$C5) + (F7 * 0.8 * 'M1 Population'!$C6) -> 185506.84 | H7: =(G6 * 0.2 * 'M1 Population'!$C5) + (G7 * 0.8 * 'M1 Population'!$C6) -> 179861.67 | I7: =(H6 * 0.2 * 'M1 Population'!$C5) + (H7 * 0.8 * 'M1 Population'!$C6) -> 174398 | J7: =(I6 * 0.2 * 'M1 Population'!$C5) + (I7 * 0.8 * 'M1 Population'!$C6) -> 169189.71 | ... L7: =(K6 * 0.2 * 'M1 Population'!$C5) + (K7 * 0.8 * 'M1 Population'!$C6) -> 159634.29 | O7: 10 - 14 Years | P7: =B7 -> 206577 | Q7: =-1*P7 -> -206577 | R7: =L7 -> 159634.29
A8: 15 - 19 Years | B8: ='M1 Population'!V79 -> 211394 | C8: =(B7 * 0.2 * 'M1 Population'!$C6) + (B8 * 0.8 * 'M1 Population'!$C7) -> 210388.44 | D8: =(C7 * 0.2 * 'M1 Population'!$C6) + (C8 * 0.8 * 'M1 Population'!$C7) -> 209308.87 | E8: =(D7 * 0.2 * 'M1 Population'!$C6) + (D8 * 0.8 * 'M1 Population'!$C7) -> 207715.08 | F8: =(E7 * 0.2 * 'M1 Population'!$C6) + (E8 * 0.8 * 'M1 Population'!$C7) -> 205465.1 | G8: =(F7 * 0.2 * 'M1 Population'!$C6) + (F8 * 0.8 * 'M1 Population'!$C7) -> 202569.68 | H8: =(G7 * 0.2 * 'M1 Population'!$C6) + (G8 * 0.8 * 'M1 Population'!$C7) -> 199117 | I8: =(H7 * 0.2 * 'M1 Population'!$C6) + (H8 * 0.8 * 'M1 Population'!$C7) -> 195226.58 | J8: =(I7 * 0.2 * 'M1 Population'!$C6) + (I8 * 0.8 * 'M1 Population'!$C7) -> 191022.31 | ... L8: =(K7 * 0.2 * 'M1 Population'!$C6) + (K8 * 0.8 * 'M1 Population'!$C7) -> 182111.15 | O8: 15 - 19 Years | P8: =B8 -> 211394 | Q8: =-1*P8 -> -211394 | R8: =L8 -> 182111.15
A9: 20 - 24 Years | B9: ='M1 Population'!V80 -> 218686 | C9: =(B8 * 0.2 * 'M1 Population'!$C7) + (B9 * 0.8 * 'M1 Population'!$C8) -> 217176.31 | D9: =(C8 * 0.2 * 'M1 Population'!$C7) + (C9 * 0.8 * 'M1 Population'!$C8) -> 215767.78 | E9: =(D8 * 0.2 * 'M1 Population'!$C7) + (D9 * 0.8 * 'M1 Population'!$C8) -> 214425.36 | F9: =(E8 * 0.2 * 'M1 Population'!$C7) + (E9 * 0.8 * 'M1 Population'!$C8) -> 213033 | G9: =(F8 * 0.2 * 'M1 Population'!$C7) + (F9 * 0.8 * 'M1 Population'!$C8) -> 211469.47 | H9: =(G8 * 0.2 * 'M1 Population'!$C7) + (G9 * 0.8 * 'M1 Population'!$C8) -> 209640 | I9: =(H8 * 0.2 * 'M1 Population'!$C7) + (H9 * 0.8 * 'M1 Population'!$C8) -> 207486.39 | J9: =(I8 * 0.2 * 'M1 Population'!$C7) + (I9 * 0.8 * 'M1 Population'!$C8) -> 204986 | ... L9: =(K8 * 0.2 * 'M1 Population'!$C7) + (K9 * 0.8 * 'M1 Population'!$C8) -> 198993 | O9: 20 - 24 Years | P9: =B9 -> 218686 | Q9: =-1*P9 -> -218686 | R9: =L9 -> 198993
A10: 25 - 29 Years | B10: ='M1 Population'!V81 -> 263735 | C10: =(B9 * 0.2 * 'M1 Population'!$C8) + (B10 * 0.8 * 'M1 Population'!$C9) -> 254651.41 | D10: =(C9 * 0.2 * 'M1 Population'!$C8) + (C10 * 0.8 * 'M1 Population'!$C9) -> 247084.85 | E10: =(D9 * 0.2 * 'M1 Population'!$C8) + (D10 * 0.8 * 'M1 Population'!$C9) -> 240751.78 | F10: =(E9 * 0.2 * 'M1 Population'!$C8) + (E10 * 0.8 * 'M1 Population'!$C9) -> 235418.42 | G10: =(F9 * 0.2 * 'M1 Population'!$C8) + (F10 * 0.8 * 'M1 Population'!$C9) -> 230874.61 | H10: =(G9 * 0.2 * 'M1 Population'!$C8) + (G10 * 0.8 * 'M1 Population'!$C9) -> 226928.02 | I10: =(H9 * 0.2 * 'M1 Population'!$C8) + (H10 * 0.8 * 'M1 Population'!$C9) -> 223405.89 | J10: =(I9 * 0.2 * 'M1 Population'!$C8) + (I10 * 0.8 * 'M1 Population'!$C9) -> 220158.41 | ... L10: =(K9 * 0.2 * 'M1 Population'!$C8) + (K10 * 0.8 * 'M1 Population'!$C9) -> 214016.31 | O10: 25 - 29 Years | P10: =B10 -> 263735 | Q10: =-1*P10 -> -263735 | R10: =L10 -> 214016.31
A11: 30 - 34 Years | B11: ='M1 Population'!V82 -> 319836 | C11: =(B10 * 0.2 * 'M1 Population'!$C9) + (B11 * 0.8 * 'M1 Population'!$C10) -> 308507.86 | D11: =(C10 * 0.2 * 'M1 Population'!$C9) + (C11 * 0.8 * 'M1 Population'!$C10) -> 297632.44 | E11: =(D10 * 0.2 * 'M1 Population'!$C9) + (D11 * 0.8 * 'M1 Population'!$C10) -> 287422.38 | F11: =(E10 * 0.2 * 'M1 Population'!$C9) + (E11 * 0.8 * 'M1 Population'!$C10) -> 277991.04 | G11: =(F10 * 0.2 * 'M1 Population'!$C9) + (F11 * 0.8 * 'M1 Population'!$C10) -> 269382.33 | H11: =(G10 * 0.2 * 'M1 Population'!$C9) + (G11 * 0.8 * 'M1 Population'!$C10) -> 261589.35 | I11: =(H10 * 0.2 * 'M1 Population'!$C9) + (H11 * 0.8 * 'M1 Population'!$C10) -> 254568.13 | J11: =(I10 * 0.2 * 'M1 Population'!$C9) + (I11 * 0.8 * 'M1 Population'!$C10) -> 248248.96 | ... L11: =(K10 * 0.2 * 'M1 Population'!$C9) + (K11 * 0.8 * 'M1 Population'!$C10) -> 237366.29 | O11: 30 - 34 Years | P11: =B11 -> 319836 | Q11: =-1*P11 -> -319836 | R11: =L11 -> 237366.29
A12: 35 - 39 Years | B12: ='M1 Population'!V83 -> 320125 | C12: =(B11 * 0.2 * 'M1 Population'!$C10) + (B12 * 0.8 * 'M1 Population'!$C11) -> 319911 | D12: =(C11 * 0.2 * 'M1 Population'!$C10) + (C12 * 0.8 * 'M1 Population'!$C11) -> 317475.08 | E12: =(D11 * 0.2 * 'M1 Population'!$C10) + (D12 * 0.8 * 'M1 Population'!$C11) -> 313353.05 | F12: =(E11 * 0.2 * 'M1 Population'!$C10) + (E12 * 0.8 * 'M1 Population'!$C11) -> 308015.87 | G12: =(F11 * 0.2 * 'M1 Population'!$C10) + (F12 * 0.8 * 'M1 Population'!$C11) -> 301862.75 | H12: =(G11 * 0.2 * 'M1 Population'!$C10) + (G12 * 0.8 * 'M1 Population'!$C11) -> 295221.7 | I12: =(H11 * 0.2 * 'M1 Population'!$C10) + (H12 * 0.8 * 'M1 Population'!$C11) -> 288353.58 | J12: =(I11 * 0.2 * 'M1 Population'!$C10) + (I12 * 0.8 * 'M1 Population'!$C11) -> 281458.21 | ... L12: =(K11 * 0.2 * 'M1 Population'!$C10) + (K12 * 0.8 * 'M1 Population'!$C11) -> 268122.62 | O12: 35 - 39 Years | P12: =B12 -> 320125 | Q12: =-1*P12 -> -320125 | R12: =L12 -> 268122.62
A13: 40 - 44 Years | B13: ='M1 Population'!V84 -> 311772 | C13: =(B12 * 0.2 * 'M1 Population'!$C11) + (B13 * 0.8 * 'M1 Population'!$C12) -> 313209.77 | D13: =(C12 * 0.2 * 'M1 Population'!$C11) + (C13 * 0.8 * 'M1 Population'!$C12) -> 314316.29 | E13: =(D12 * 0.2 * 'M1 Population'!$C11) + (D13 * 0.8 * 'M1 Population'!$C12) -> 314713.87 | F13: =(E12 * 0.2 * 'M1 Population'!$C11) + (E13 * 0.8 * 'M1 Population'!$C12) -> 314207.7 | G13: =(F12 * 0.2 * 'M1 Population'!$C11) + (F13 * 0.8 * 'M1 Population'!$C12) -> 312736.21 | H13: =(G12 * 0.2 * 'M1 Population'!$C11) + (G13 * 0.8 * 'M1 Population'!$C12) -> 310329.97 | I13: =(H12 * 0.2 * 'M1 Population'!$C11) + (H13 * 0.8 * 'M1 Population'!$C12) -> 307079 | J13: =(I12 * 0.2 * 'M1 Population'!$C11) + (I13 * 0.8 * 'M1 Population'!$C12) -> 303107.4 | ... L13: =(K12 * 0.2 * 'M1 Population'!$C11) + (K13 * 0.8 * 'M1 Population'!$C12) -> 293560.08 | O13: 40 - 44 Years | P13: =B13 -> 311772 | Q13: =-1*P13 -> -311772 | R13: =L13 -> 293560.08
A14: 45 - 49 Years | B14: ='M1 Population'!V85 -> 302015 | C14: =(B13 * 0.2 * 'M1 Population'!$C12) + (B14 * 0.8 * 'M1 Population'!$C13) -> 303592.76 | D14: =(C13 * 0.2 * 'M1 Population'!$C12) + (C14 * 0.8 * 'M1 Population'!$C13) -> 305140.59 | E14: =(D13 * 0.2 * 'M1 Population'!$C12) + (D14 * 0.8 * 'M1 Population'!$C13) -> 306598.33 | F14: =(E13 * 0.2 * 'M1 Population'!$C12) + (E14 * 0.8 * 'M1 Population'!$C13) -> 307842.41 | G14: =(F13 * 0.2 * 'M1 Population'!$C12) + (F14 * 0.8 * 'M1 Population'!$C13) -> 308735.19 | H14: =(G13 * 0.2 * 'M1 Population'!$C12) + (G14 * 0.8 * 'M1 Population'!$C13) -> 309154.39 | I14: =(H13 * 0.2 * 'M1 Population'!$C12) + (H14 * 0.8 * 'M1 Population'!$C13) -> 309008.44 | J14: =(I13 * 0.2 * 'M1 Population'!$C12) + (I14 * 0.8 * 'M1 Population'!$C13) -> 308242.16 | ... L14: =(K13 * 0.2 * 'M1 Population'!$C12) + (K14 * 0.8 * 'M1 Population'!$C13) -> 304803.19 | O14: 45 - 49 Years | P14: =B14 -> 302015 | Q14: =-1*P14 -> -302015 | R14: =L14 -> 304803.19
A15: 50 - 54 Years | B15: ='M1 Population'!V86 -> 308978 | C15: =(B14 * 0.2 * 'M1 Population'!$C13) + (B15 * 0.8 * 'M1 Population'!$C14) -> 306955.72 | D15: =(C14 * 0.2 * 'M1 Population'!$C13) + (C15 * 0.8 * 'M1 Population'!$C14) -> 305656.61 | E15: =(D14 * 0.2 * 'M1 Population'!$C13) + (D15 * 0.8 * 'M1 Population'!$C14) -> 304928.78 | F15: =(E14 * 0.2 * 'M1 Population'!$C13) + (E15 * 0.8 * 'M1 Population'!$C14) -> 304638.97 | G15: =(F14 * 0.2 * 'M1 Population'!$C13) + (F15 * 0.8 * 'M1 Population'!$C14) -> 304656.12 | H15: =(G14 * 0.2 * 'M1 Population'!$C13) + (G15 * 0.8 * 'M1 Population'!$C14) -> 304848.12 | I15: =(H14 * 0.2 * 'M1 Population'!$C13) + (H15 * 0.8 * 'M1 Population'!$C14) -> 305085.11 | J15: =(I14 * 0.2 * 'M1 Population'!$C13) + (I15 * 0.8 * 'M1 Population'!$C14) -> 305245.13 | ... L15: =(K14 * 0.2 * 'M1 Population'!$C13) + (K15 * 0.8 * 'M1 Population'!$C14) -> 304918.8 | O15: 50 - 54 Years | P15: =B15 -> 308978 | Q15: =-1*P15 -> -308978 | R15: =L15 -> 304918.8
A16: 55 - 59 Years | B16: ='M1 Population'!V87 -> 289783 | C16: =(B15 * 0.2 * 'M1 Population'!$C14) + (B16 * 0.8 * 'M1 Population'!$C15) -> 292654.88 | D16: =(C15 * 0.2 * 'M1 Population'!$C14) + (C16 * 0.8 * 'M1 Population'!$C15) -> 294540.59 | E16: =(D15 * 0.2 * 'M1 Population'!$C14) + (D16 * 0.8 * 'M1 Population'!$C15) -> 295784.52 | F16: =(E15 * 0.2 * 'M1 Population'!$C14) + (E16 * 0.8 * 'M1 Population'!$C15) -> 296630.86 | G16: =(F15 * 0.2 * 'M1 Population'!$C14) + (F16 * 0.8 * 'M1 Population'!$C15) -> 297247.67 | H16: =(G15 * 0.2 * 'M1 Population'!$C14) + (G16 * 0.8 * 'M1 Population'!$C15) -> 297742.77 | I16: =(H15 * 0.2 * 'M1 Population'!$C14) + (H16 * 0.8 * 'M1 Population'!$C15) -> 298175.76 | J16: =(I15 * 0.2 * 'M1 Population'!$C14) + (I16 * 0.8 * 'M1 Population'!$C15) -> 298568.19 | ... L16: =(K15 * 0.2 * 'M1 Population'!$C14) + (K16 * 0.8 * 'M1 Population'!$C15) -> 299182.72 | O16: 55 - 59 Years | P16: =B16 -> 289783 | Q16: =-1*P16 -> -289783 | R16: =L16 -> 299182.72
A17: 60 - 64 Years | B17: ='M1 Population'!V88 -> 296675 | C17: =(B16 * 0.2 * 'M1 Population'!$C15) + (B17 * 0.8 * 'M1 Population'!$C16) -> 293674.57 | D17: =(C16 * 0.2 * 'M1 Population'!$C15) + (C17 * 0.8 * 'M1 Population'!$C16) -> 291860.85 | E17: =(D16 * 0.2 * 'M1 Population'!$C15) + (D17 * 0.8 * 'M1 Population'!$C16) -> 290794.31 | F17: =(E16 * 0.2 * 'M1 Population'!$C15) + (E17 * 0.8 * 'M1 Population'!$C16) -> 290194.07 | G17: =(F16 * 0.2 * 'M1 Population'!$C15) + (F17 * 0.8 * 'M1 Population'!$C16) -> 289885.39 | H17: =(G16 * 0.2 * 'M1 Population'!$C15) + (G17 * 0.8 * 'M1 Population'!$C16) -> 289762.84 | I17: =(H16 * 0.2 * 'M1 Population'!$C15) + (H17 * 0.8 * 'M1 Population'!$C16) -> 289764.06 | J17: =(I16 * 0.2 * 'M1 Population'!$C15) + (I17 * 0.8 * 'M1 Population'!$C16) -> 289851.31 | ... L17: =(K16 * 0.2 * 'M1 Population'!$C15) + (K17 * 0.8 * 'M1 Population'!$C16) -> 290184.97 | O17: 60 - 64 Years | P17: =B17 -> 296675 | Q17: =-1*P17 -> -296675 | R17: =L17 -> 290184.97
A18: 65 - 69 Years | B18: ='M1 Population'!V89 -> 272419 | C18: =(B17 * 0.2 * 'M1 Population'!$C16) + (B18 * 0.8 * 'M1 Population'!$C17) -> 274820.03 | D18: =(C17 * 0.2 * 'M1 Population'!$C16) + (C18 * 0.8 * 'M1 Population'!$C17) -> 276125.86 | E18: =(D17 * 0.2 * 'M1 Population'!$C16) + (D18 * 0.8 * 'M1 Population'!$C17) -> 276799.9 | F18: =(E17 * 0.2 * 'M1 Population'!$C16) + (E18 * 0.8 * 'M1 Population'!$C17) -> 277121.9 | G18: =(F17 * 0.2 * 'M1 Population'!$C16) + (F18 * 0.8 * 'M1 Population'!$C17) -> 277257.69 | H18: =(G17 * 0.2 * 'M1 Population'!$C16) + (G18 * 0.8 * 'M1 Population'!$C17) -> 277303.91 | I18: =(H17 * 0.2 * 'M1 Population'!$C16) + (H18 * 0.8 * 'M1 Population'!$C17) -> 277316.17 | J18: =(I17 * 0.2 * 'M1 Population'!$C16) + (I18 * 0.8 * 'M1 Population'!$C17) -> 277326.12 | ... L18: =(K17 * 0.2 * 'M1 Population'!$C16) + (K18 * 0.8 * 'M1 Population'!$C17) -> 277400.69 | O18: 65 - 69 Years | P18: =B18 -> 272419 | Q18: =-1*P18 -> -272419 | R18: =L18 -> 277400.69
... A22: 85 - 89 Years | B22: ='M1 Population'!V93 -> 47550 | C22: =(B21 * 0.2 * 'M1 Population'!$C20) + (B22 * 0.8 * 'M1 Population'!$C21) -> 48758.323 | D22: =(C21 * 0.2 * 'M1 Population'!$C20) + (C22 * 0.8 * 'M1 Population'!$C21) -> 51877.426 | E22: =(D21 * 0.2 * 'M1 Population'!$C20) + (D22 * 0.8 * 'M1 Population'!$C21) -> 56159.035 | F22: =(E21 * 0.2 * 'M1 Population'!$C20) + (E22 * 0.8 * 'M1 Population'!$C21) -> 61105.794 | G22: =(F21 * 0.2 * 'M1 Population'!$C20) + (F22 * 0.8 * 'M1 Population'!$C21) -> 66383.752 | H22: =(G21 * 0.2 * 'M1 Population'!$C20) + (G22 * 0.8 * 'M1 Population'!$C21) -> 71765.485 | I22: =(H21 * 0.2 * 'M1 Population'!$C20) + (H22 * 0.8 * 'M1 Population'!$C21) -> 77093.963 | J22: =(I21 * 0.2 * 'M1 Population'!$C20) + (I22 * 0.8 * 'M1 Population'!$C21) -> 82259.921 | ... L22: =(K21 * 0.2 * 'M1 Population'!$C20) + (K22 * 0.8 * 'M1 Population'!$C21) -> 91826.448 | O22: 85 - 89 Years | P22: =B22 -> 47550 | Q22: =-1*P22 -> -47550 | R22: =L22 -> 91826.448
A23: 90 Years & Over | B23: ='M1 Population'!V94 -> 27360 | C23: =(B22*0.2*'M1 Population'!$C$21) + (B23*'M1 Population'!$C$22) -> 31383.135 | D23: =(C22*0.2*'M1 Population'!$C$21) + (C23*'M1 Population'!$C$22) -> 34947.425 | E23: =(D22*0.2*'M1 Population'!$C$21) + (D23*'M1 Population'!$C$22) -> 38477.267 | F23: =(E22*0.2*'M1 Population'!$C$21) + (E23*'M1 Population'!$C$22) -> 42189.604 | G23: =(F22*0.2*'M1 Population'!$C$21) + (F23*'M1 Population'!$C$22) -> 46174.471 | H23: =(G22*0.2*'M1 Population'!$C$21) + (G23*'M1 Population'!$C$22) -> 50446.072 | I23: =(H22*0.2*'M1 Population'!$C$21) + (H23*'M1 Population'!$C$22) -> 54974.912 | J23: =(I22*0.2*'M1 Population'!$C$21) + (I23*'M1 Population'!$C$22) -> 59707.947 | ... L23: =(K22*0.2*'M1 Population'!$C$21) + (K23*'M1 Population'!$C$22) -> 69527.874 | O23: 90 Years & Over | P23: =B23 -> 27360 | Q23: =-1*P23 -> -27360 | R23: =L23 -> 69527.874
A24: TOTAL | B24: =SUM(B4:B23) -> 4204515 | C24: =SUM(C4:C23) -> 4204434.4 | D24: =SUM(D4:D23) -> 4201945 | E24: =SUM(E4:E23) -> 4197066.8 | F24: =SUM(F4:F23) -> 4189808.3 | G24: =SUM(G4:G23) -> 4180178.9 | H24: =SUM(H4:H23) -> 4168197.6 | I24: =SUM(I4:I23) -> 4153896.3 | ... L24: =SUM(L4:L23) -> 4097610.2
A27: Group | B27: 2005 | C27: 2006 | D27: 2007 | E27: 2008 | F27: 2009 | G27: 2010 | H27: 2011 | I27: 2012 | J27: 2013 | K27: 2014 | L27: 2015 | M27: 2016 | N27: 2017 | O27: 2018 | P27: 2019 | Q27: 2020 | R27: 2021 | S27: 2022 | T27: 2023 | U27: 2024 | V27: 2025 | W27: 2026 | X27: 2027 | Y27: 2028 | Z27: 2029 | AA27: 2030 | AB27: 2031 | AC27: 2032 | AD27: 2033 | AE27: 2034 | AF27: 2035
A28: Working age (15-64) | B28: =SUM('M1 Population'!B79:B88) -> 2492802 | C28: =SUM('M1 Population'!C79:C88) -> 2545003 | D28: =SUM('M1 Population'!D79:D88) -> 2599037 | E28: =SUM('M1 Population'!E79:E88) -> 2655562 | F28: =SUM('M1 Population'!F79:F88) -> 2735893 | G28: =SUM('M1 Population'!G79:G88) -> 2778925 | H28: =SUM('M1 Population'!H79:H88) -> 2799702 | I28: =SUM('M1 Population'!I79:I88) -> 2813252 | ... U28: =SUM('M1 Population'!U79:U88) -> 2849994 | V28: =SUM(B8:B17) -> 2842999 | W28: =SUM(C8:C17) -> 2820722.7 | X28: =SUM(D8:D17) -> 2798784 | Y28: =SUM(E8:E17) -> 2776487.5 | Z28: =SUM(F8:F17) -> 2753437.4 | AA28: =SUM(G8:G17) -> 2729419.4 | AB28: =SUM(H8:H17) -> 2704334.2 | AC28: =SUM(I8:I17) -> 2678152.9 | ... AF28: =SUM(L8:L17) -> 2593259.1
A29: Seniors (65+) | B29: =SUM('M1 Population'!B89:B94) -> 279693 | C29: =SUM('M1 Population'!C89:C94) -> 294726 | D29: =SUM('M1 Population'!D89:D94) -> 305586 | E29: =SUM('M1 Population'!E89:E94) -> 315790 | F29: =SUM('M1 Population'!F89:F94) -> 330132 | G29: =SUM('M1 Population'!G89:G94) -> 338387 | H29: =SUM('M1 Population'!H89:H94) -> 352645 | I29: =SUM('M1 Population'!I89:I94) -> 378636 | ... U29: =SUM('M1 Population'!U89:U94) -> 753905 | V29: =SUM(B18:B23) -> 789576 | W29: =SUM(C18:C23) -> 825848.54 | X29: =SUM(D18:D23) -> 859768.62 | Y29: =SUM(E18:E23) -> 891569.58 | Z29: =SUM(F18:F23) -> 921382.63 | AA29: =SUM(G18:G23) -> 949284.3 | AB29: =SUM(H18:H23) -> 975326.17 | AC29: =SUM(I18:I23) -> 999552.82 | ... AF29: =SUM(L18:L23) -> 1061853.8
A30: Dependency ratio | B30: =(B29/B28)*100 -> 11.220025 | C30: =(C29/C28)*100 -> 11.580576 | D30: =(D29/D28)*100 -> 11.757663 | E30: =(E29/E28)*100 -> 11.891645 | F30: =(F29/F28)*100 -> 12.0667 | G30: =(G29/G28)*100 -> 12.176903 | H30: =(H29/H28)*100 -> 12.595805 | I30: =(I29/I28)*100 -> 13.459015 | ... AF30: =(AF29/AF28)*100 -> 40.94669
B32: Actual | C32: Projected
A33: 2005 | B33: ='M1 Population'!B95 -> 3467814
A34: 2006 | B34: ='M1 Population'!C95 -> 3525894
A35: 2007 | B35: ='M1 Population'!D95 -> 3583082
A36: 2008 | B36: ='M1 Population'!E95 -> 3642659
A37: 2009 | B37: ='M1 Population'!F95 -> 3733876
A38: 2010 | B38: ='M1 Population'!G95 -> 3771721
A39: 2011 | B39: ='M1 Population'!H95 -> 3789251
A40: 2012 | B40: ='M1 Population'!I95 -> 3818205
A41: 2013 | B41: ='M1 Population'!J95 -> 3844751
A42: 2014 | B42: ='M1 Population'!K95 -> 3870739
A43: 2015 | B43: ='M1 Population'!L95 -> 3902690
A44: 2016 | B44: ='M1 Population'!M95 -> 3933559
A45: 2017 | B45: ='M1 Population'!N95 -> 3965796
A46: 2018 | B46: ='M1 Population'!O95 -> 3994283
A47: 2019 | B47: ='M1 Population'!P95 -> 4026209
...

Sheet M2 HAR
A1: Hospital Admission Rate | B1: 2024 | C1: 2023 | D1: 2022 | E1: 2021 | F1: 2020 | G1: 2019 | H1: 2018 | I1: 2017 | J1: 2016 | K1: 2015 | L1: 2014 | M1: 2013 | N1: 2012 | O1: 2011 | P1: 2010 | Q1: 2009 | R1: 2008 | S1: 2007 | T1: 2006
A2: Acute Hospitals - Male | B2: 138.6 | C2: 137.5 | D2: 133.9 | E2: 128.2 | F2: 121.8 | G2: 136.8 | H2: 130 | I2: 127.4 | J2: 123.7 | K2: 110.5 | L2: 108.2 | M2: 104.5 | N2: 100.7 | O2: 96.9 | P2: 93.2 | Q2: 90.2 | R2: 90.6 | S2: 91 | T2: 90.2
A3: 0 - 14 Years Old | B3: 135.4 | C3: 139.5 | D3: 140.4 | E3: 119.7 | F3: 110.9 | G3: 148.4 | H3: 145.4 | I3: 142.7 | J3: 142.1 | K3: 128.5 | L3: 126.6 | M3: 120.2 | N3: 118.5 | O3: 111.6 | P3: 104.3 | Q3: 100.1 | R3: 99.2 | S3: 95 | T3: 92.5
A4: 15 - 64 Years Old | B4: 82.4 | C4: 81.1 | D4: 78.7 | E4: 82.7 | F4: 80.3 | G4: 88.8 | H4: 84.3 | I4: 83.8 | J4: 81.5 | K4: 71.5 | L4: 71 | M4: 70 | N4: 66.7 | O4: 65.4 | P4: 63.8 | Q4: 62.7 | R4: 62.6 | S4: 63.9 | T4: 64
A5: 65 Years Old & Above | B5: 366 | C5: 373.4 | D5: 371.8 | E5: 348.4 | F5: 338.4 | G5: 376.5 | H5: 368.2 | I5: 369.1 | J5: 366.7 | K5: 347.6 | L5: 347.7 | M5: 343.7 | N5: 347.6 | O5: 345.2 | P5: 339.6 | Q5: 323 | R5: 333.2 | S5: 340.4 | T5: 337.9
A6: Acute Hospitals - Female | B6: 132.1 | C6: 131.5 | D6: 129.4 | E6: 126.2 | F6: 117.4 | G6: 135.6 | H6: 129.6 | I6: 127.4 | J6: 123.4 | K6: 111.9 | L6: 111 | M6: 107.7 | N6: 105.5 | O6: 102.7 | P6: 98.3 | Q6: 96.4 | R6: 98.1 | S6: 99.4 | T6: 98.3
A7: 0 - 14 Years Old | B7: 119.5 | C7: 121.8 | D7: 123.4 | E7: 109.4 | F7: 98 | G7: 131.8 | H7: 127 | I7: 124.3 | J7: 121.5 | K7: 112 | L7: 109.4 | M7: 102 | N7: 101.2 | O7: 95.6 | P7: 88 | Q7: 84.9 | R7: 86.6 | S7: 83.2 | T7: 81.4
A8: 15 - 64 Years Old | B8: 86.4 | C8: 86.5 | D8: 86.1 | E8: 90.3 | F8: 85.2 | G8: 96.5 | H8: 92.3 | I8: 90.6 | J8: 88.6 | K8: 80.1 | L8: 80 | M8: 78.3 | N8: 77.2 | O8: 75.7 | P8: 74.2 | Q8: 73.5 | R8: 75 | S8: 77.3 | T8: 77.4
A9: 65 Years Old & Above | B9: 305.3 | C9: 307.7 | D9: 303.7 | E9: 286 | F9: 274.6 | G9: 318.9 | H9: 313.8 | I9: 319.8 | J9: 314.1 | K9: 292.9 | L9: 299.9 | M9: 302.6 | N9: 304 | O9: 308 | P9: 295.3 | Q9: 287.7 | R9: 294.8 | S9: 299.8 | T9: 295.7
A10: Psychiatric Hospitals - Male | B10: 2.6 | C10: 2.7 | D10: 2.5 | E10: 2.2 | F10: 2.4 | G10: 2.6 | H10: 2.7 | I10: 2.7 | J10: 2.7 | K10: 2.6 | L10: 2.4 | M10: 2.2 | N10: 2.3 | O10: 2.8 | P10: 2.8 | Q10: 2.7 | R10: 2.6 | S10: 2.5 | T10: 2.5
A11: 0 - 14 Years Old | B11: 0.1 | C11: 0.2 | D11: 0.1 | E11: 0.2 | F11: 0.1 | G11: 0.1 | H11: 0.1 | I11: 0.2 | J11: 0.2 | K11: 0.1 | L11: 0.2 | M11: 0.2 | N11: 0.1 | O11: 0.1 | P11: 0.2 | Q11: 0.1 | R11: 0.1 | S11: 0.1 | T11: 0.1
A12: 15 - 64 Years Old | B12: 3 | C12: 3.2 | D12: 3 | E12: 2.7 | F12: 2.9 | G12: 3.2 | H12: 3.3 | I12: 3.3 | J12: 3.3 | K12: 3.2 | L12: 3 | M12: 2.7 | N12: 2.8 | O12: 3.5 | P12: 3.5 | Q12: 3.3 | R12: 3.3 | S12: 3.1 | T12: 3.2
... A18: Community Hospitals - Male | B18: 5.6 | C18: 4.6 | D18: 5.2 | E18: 5 | F18: 4.4 | G18: 4.5 | H18: 4.1 | I18: 3.7 | J18: 3.1 | K18: 2.2 | L18: 1.9 | M18: 1.8 | N18: 1.6 | O18: 1.7 | P18: 1.7 | Q18: 1.5 | R18: 1.4 | S18: 1.3 | T18: 1.2
A19: 0 - 14 Years Old | B19: 0 | C19: 0.1 | D19: 0 | E19: 0 | F19: 0 | G19: 0 | H19: 0.1 | I19: 0.1 | J19: 0.1 | K19: 0 | L19: 0 | M19: 0 | N19: 0 | O19: - | P19: - | Q19: - | R19: 0.1 | S19: - | T19: 0
A20: 15 - 64 Years Old | B20: 1.4 | C20: 1.3 | D20: 1.4 | E20: 1.8 | F20: 1.5 | G20: 1.5 | H20: 1.3 | I20: 1.2 | J20: 1.1 | K20: 0.7 | L20: 0.6 | M20: 0.6 | N20: 0.6 | O20: 0.6 | P20: 0.7 | Q20: 0.6 | R20: 0.5 | S20: 0.5 | T20: 0.5
A21: 65 Years Old & Above | B21: 27 | C21: 22.5 | D21: 26.7 | E21: 25 | F21: 23.4 | G21: 25.6 | H21: 24.1 | I21: 23.4 | J21: 20.3 | K21: 15.6 | L21: 14.4 | M21: 13.9 | N21: 13 | O21: 14.9 | P21: 14.9 | Q21: 13.6 | R21: 13.5 | S21: 12.8 | T21: 12.2
A22: Community Hospitals - Female | B22: 6.6 | C22: 5.2 | D22: 5.2 | E22: 5.1 | F22: 4.4 | G22: 5.1 | H22: 4.6 | I22: 4.3 | J22: 3.7 | K22: 2.7 | L22: 2.4 | M22: 2.3 | N22: 2.1 | O22: 2.1 | P22: 2 | Q22: 1.9 | R22: 1.9 | S22: 1.6 | T22: 1.6
A23: 0 - 14 Years Old | B23: 0 | C23: 0.1 | D23: 0.1 | E23: 0 | F23: 0 | G23: 0 | H23: 0 | I23: 0 | J23: 0 | K23: 0 | L23: 0 | M23: 0 | N23: 0 | O23: - | P23: - | Q23: - | R23: - | S23: - | T23: 0
A24: 15 - 64 Years Old | B24: 1.2 | C24: 1 | D24: 1 | E24: 1.3 | F24: 1.1 | G24: 1.1 | H24: 1 | I24: 0.9 | J24: 0.8 | K24: 0.6 | L24: 0.5 | M24: 0.5 | N24: 0.5 | O24: 0.5 | P24: 0.4 | Q24: 0.4 | R24: 0.4 | S24: 0.4 | T24: 0.4
A25: 65 Years Old & Above | B25: 30.4 | C25: 24.8 | D25: 25.5 | E25: 24.8 | F25: 23 | G25: 27.9 | H25: 26.7 | I25: 26.2 | J25: 23.3 | K25: 18 | L25: 16.7 | M25: 16.8 | N25: 16 | O25: 17.5 | P25: 16.9 | Q25: 16.4 | R25: 16.4 | S25: 14.4 | T25: 14.1
D27: =_xlfn.FORMULATEXT(B33) -> =MAX(0,FORECAST.LINEAR(B31, $B$3:$T$3, $B$1:$T$1))
A28: Projected Admissions | D28: =_xlfn.FORMULATEXT(B35) -> =MAX(0,FORECAST.LINEAR(B31, $B$5:$T$5, $B$1:$T$1)*(1+$B$29)^(B31-$B$1))
A29: Government Policy Factor(r) | B29: ='M2 BOR & Tradeoff analysis'!B12 -> -0.006 | D29: Adjusted Rate_year ​ =Linear Forecast Rate×(1−r)^(Year−2024)
B30: -0.6 to 0
A31: Hospital Admission Rate | B31: 2035 | C31: =B31-1 -> 2034 | D31: =C31-1 -> 2033 | E31: =D31-1 -> 2032 | F31: =E31-1 -> 2031 | G31: =F31-1 -> 2030 | H31: =G31-1 -> 2029 | I31: =H31-1 -> 2028 | J31: =I31-1 -> 2027 | ... L31: =K31-1 -> 2025 | M31: 2024 | N31: 2023 | O31: 2022 | P31: 2021 | Q31: 2020 | R31: 2019 | S31: 2018 | T31: 2017 | U31: 2016 | V31: 2015 | W31: 2014 | X31: 2013 | Y31: 2012 | Z31: 2011 | AA31: 2010 | AB31: 2009 | AC31: 2008 | AD31: 2007 | AE31: 2006
A32: Acute Hospitals - Male - Projected
A33: 0 - 14 Years Old | B33: =MAX(0,_xlfn.FORECAST.LINEAR(B31, $B$3:$T$3, $B$1:$T$1)) -> 173.7193 | C33: =MAX(0,_xlfn.FORECAST.LINEAR(C31, $B$3:$T$3, $B$1:$T$1)) -> 171.14123 | D33: =MAX(0,_xlfn.FORECAST.LINEAR(D31, $B$3:$T$3, $B$1:$T$1)) -> 168.56316 | E33: =MAX(0,_xlfn.FORECAST.LINEAR(E31, $B$3:$T$3, $B$1:$T$1)) -> 165.98509 | F33: =MAX(0,_xlfn.FORECAST.LINEAR(F31, $B$3:$T$3, $B$1:$T$1)) -> 163.40702 | G33: =MAX(0,_xlfn.FORECAST.LINEAR(G31, $B$3:$T$3, $B$1:$T$1)) -> 160.82895 | H33: =MAX(0,_xlfn.FORECAST.LINEAR(H31, $B$3:$T$3, $B$1:$T$1)) -> 158.25088 | I33: =MAX(0,_xlfn.FORECAST.LINEAR(I31, $B$3:$T$3, $B$1:$T$1)) -> 155.67281 | ... L33: =MAX(0,_xlfn.FORECAST.LINEAR(L31, $B$3:$T$3, $B$1:$T$1)) -> 147.9386
A34: 15 - 64 Years Old | B34: =(SUM('M1 Demand Driver'!L8:L16)/SUM('M1 Demand Driver'!L8:L17)*MAX(0,_xlfn.FORECAST.LINEAR(B31,$B$4:$T$4,$B$1:$T$1)))+('M1 Demand Driver'!L17/SUM('M1 Demand Driver'!L8:L17)*MAX(0,_xlfn.FORECAST.LINEAR(B31,$B$4:$T$4,$B$1:$T$1)*(1+$B$29)^(B31-$B$1))) -> 101.39778 | C34: =(SUM('M1 Demand Driver'!K8:K16)/SUM('M1 Demand Driver'!K8:K17)*MAX(0,_xlfn.FORECAST.LINEAR(C31,$B$4:$T$4,$B$1:$T$1)))+('M1 Demand Driver'!K17/SUM('M1 Demand Driver'!K8:K17)*MAX(0,_xlfn.FORECAST.LINEAR(C31,$B$4:$T$4,$B$1:$T$1)*(1+$B$29)^(C31-$B$1))) -> 100.07073 | D34: =(SUM('M1 Demand Driver'!J8:J16)/SUM('M1 Demand Driver'!J8:J17)*MAX(0,_xlfn.FORECAST.LINEAR(D31,$B$4:$T$4,$B$1:$T$1)))+('M1 Demand Driver'!J17/SUM('M1 Demand Driver'!J8:J17)*MAX(0,_xlfn.FORECAST.LINEAR(D31,$B$4:$T$4,$B$1:$T$1)*(1+$B$29)^(D31-$B$1))) -> 98.740126 | E34: =(SUM('M1 Demand Driver'!I8:I16)/SUM('M1 Demand Driver'!I8:I17)*MAX(0,_xlfn.FORECAST.LINEAR(E31,$B$4:$T$4,$B$1:$T$1)))+('M1 Demand Driver'!I17/SUM('M1 Demand Driver'!I8:I17)*MAX(0,_xlfn.FORECAST.LINEAR(E31,$B$4:$T$4,$B$1:$T$1)*(1+$B$29)^(E31-$B$1))) -> 97.406132 | F34: =(SUM('M1 Demand Driver'!H8:H16)/SUM('M1 Demand Driver'!H8:H17)*MAX(0,_xlfn.FORECAST.LINEAR(F31,$B$4:$T$4,$B$1:$T$1)))+('M1 Demand Driver'!H17/SUM('M1 Demand Driver'!H8:H17)*MAX(0,_xlfn.FORECAST.LINEAR(F31,$B$4:$T$4,$B$1:$T$1)*(1+$B$29)^(F31-$B$1))) -> 96.068929 | G34: =(SUM('M1 Demand Driver'!G8:G16)/SUM('M1 Demand Driver'!G8:G17)*MAX(0,_xlfn.FORECAST.LINEAR(G31,$B$4:$T$4,$B$1:$T$1)))+('M1 Demand Driver'!G17/SUM('M1 Demand Driver'!G8:G17)*MAX(0,_xlfn.FORECAST.LINEAR(G31,$B$4:$T$4,$B$1:$T$1)*(1+$B$29)^(G31-$B$1))) -> 94.72869 | H34: =(SUM('M1 Demand Driver'!F8:F16)/SUM('M1 Demand Driver'!F8:F17)*MAX(0,_xlfn.FORECAST.LINEAR(H31,$B$4:$T$4,$B$1:$T$1)))+('M1 Demand Driver'!F17/SUM('M1 Demand Driver'!F8:F17)*MAX(0,_xlfn.FORECAST.LINEAR(H31,$B$4:$T$4,$B$1:$T$1)*(1+$B$29)^(H31-$B$1))) -> 93.385587 | I34: =(SUM('M1 Demand Driver'!E8:E16)/SUM('M1 Demand Driver'!E8:E17)*MAX(0,_xlfn.FORECAST.LINEAR(I31,$B$4:$T$4,$B$1:$T$1)))+('M1 Demand Driver'!E17/SUM('M1 Demand Driver'!E8:E17)*MAX(0,_xlfn.FORECAST.LINEAR(I31,$B$4:$T$4,$B$1:$T$1)*(1+$B$29)^(I31-$B$1))) -> 92.039796 | J34: =(SUM('M1 Demand Driver'!D8:D16)/SUM('M1 Demand Driver'!D8:D17)*MAX(0,_xlfn.FORECAST.LINEAR(J31,$B$4:$T$4,$B$1:$T$1)))+('M1 Demand Driver'!D17/SUM('M1 Demand Driver'!D8:D17)*MAX(0,_xlfn.FORECAST.LINEAR(J31,$B$4:$T$4,$B$1:$T$1)*(1+$B$29)^(J31-$B$1))) -> 90.691522 | K34: =(SUM('M1 Demand Driver'!C8:C16)/SUM('M1 Demand Driver'!C8:C17)*MAX(0,_xlfn.FORECAST.LINEAR(K31, $B$4:$T$4, $B$1:$T$1)))+('M1 Demand Driver'!C17/SUM('M1 Demand Driver'!C8:C17)*MAX(0,_xlfn.FORECAST.LINEAR(K31, $B$4:$T$4, $B$1:$T$1)*(1+$B$29)^(K31-$B$1))) -> 89.341033 | L34: =(SUM('M1 Demand Driver'!B8:B16)/SUM('M1 Demand Driver'!B8:B17)*MAX(0,_xlfn.FORECAST.LINEAR(L31,$B$4:$T$4,$B$1:$T$1)))+('M1 Demand Driver'!B17/SUM('M1 Demand Driver'!B8:B17)*MAX(0,_xlfn.FORECAST.LINEAR(L31,$B$4:$T$4,$B$1:$T$1)*(1+$B$29)^(L31-$B$1))) -> 87.988734
A35: 65 Years Old & Above | B35: =MAX(0,_xlfn.FORECAST.LINEAR(B31, $B$5:$T$5, $B$1:$T$1)*(1+$B$29)^(B31-$B$1)) -> 368.36488 | C35: =MAX(0,_xlfn.FORECAST.LINEAR(C31, $B$5:$T$5, $B$1:$T$1)*(1+$B$29)^(C31-$B$1)) -> 368.62213 | D35: =MAX(0,_xlfn.FORECAST.LINEAR(D31, $B$5:$T$5, $B$1:$T$1)*(1+$B$29)^(D31-$B$1)) -> 368.86906 | E35: =MAX(0,_xlfn.FORECAST.LINEAR(E31, $B$5:$T$5, $B$1:$T$1)*(1+$B$29)^(E31-$B$1)) -> 369.10555 | F35: =MAX(0,_xlfn.FORECAST.LINEAR(F31, $B$5:$T$5, $B$1:$T$1)*(1+$B$29)^(F31-$B$1)) -> 369.33145 | G35: =MAX(0,_xlfn.FORECAST.LINEAR(G31, $B$5:$T$5, $B$1:$T$1)*(1+$B$29)^(G31-$B$1)) -> 369.54662 | H35: =MAX(0,_xlfn.FORECAST.LINEAR(H31, $B$5:$T$5, $B$1:$T$1)*(1+$B$29)^(H31-$B$1)) -> 369.75094 | I35: =MAX(0,_xlfn.FORECAST.LINEAR(I31, $B$5:$T$5, $B$1:$T$1)*(1+$B$29)^(I31-$B$1)) -> 369.94426 | ... L35: =MAX(0,_xlfn.FORECAST.LINEAR(L31, $B$5:$T$5, $B$1:$T$1)*(1+$B$29)^(L31-$B$1)) -> 370.45682
A36: Acute Hospitals - Female - Projected
A37: 0 - 14 Years Old | B37: =MAX(0,_xlfn.FORECAST.LINEAR(B31, $B$7:$T$7, $B$1:$T$1)) -> 154.97193 | C37: =MAX(0,_xlfn.FORECAST.LINEAR(C31, $B$7:$T$7, $B$1:$T$1)) -> 152.54175 | D37: =MAX(0,_xlfn.FORECAST.LINEAR(D31, $B$7:$T$7, $B$1:$T$1)) -> 150.11158 | E37: =MAX(0,_xlfn.FORECAST.LINEAR(E31, $B$7:$T$7, $B$1:$T$1)) -> 147.6814 | F37: =MAX(0,_xlfn.FORECAST.LINEAR(F31, $B$7:$T$7, $B$1:$T$1)) -> 145.25123 | G37: =MAX(0,_xlfn.FORECAST.LINEAR(G31, $B$7:$T$7, $B$1:$T$1)) -> 142.82105 | H37: =MAX(0,_xlfn.FORECAST.LINEAR(H31, $B$7:$T$7, $B$1:$T$1)) -> 140.39088 | I37: =MAX(0,_xlfn.FORECAST.LINEAR(I31, $B$7:$T$7, $B$1:$T$1)) -> 137.9607 | ... L37: =MAX(0,_xlfn.FORECAST.LINEAR(L31, $B$7:$T$7, $B$1:$T$1)) -> 130.67018
A38: 15 - 64 Years Old | B38: =(SUM('M1 Demand Driver'!L8:L16)/SUM('M1 Demand Driver'!L8:L17)*MAX(0,_xlfn.FORECAST.LINEAR(B31,$B$8:$T$8,$B$1:$T$1)))+('M1 Demand Driver'!L17/SUM('M1 Demand Driver'!L8:L17)*MAX(0,_xlfn.FORECAST.LINEAR(B31,$B$8:$T$8,$B$1:$T$1)*(1+$B$29)^(B31-$B$1))) -> 101.25495 | C38: =(SUM('M1 Demand Driver'!K8:K16)/SUM('M1 Demand Driver'!K8:K17)*MAX(0,_xlfn.FORECAST.LINEAR(C31,$B$8:$T$8,$B$1:$T$1)))+('M1 Demand Driver'!K17/SUM('M1 Demand Driver'!K8:K17)*MAX(0,_xlfn.FORECAST.LINEAR(C31,$B$8:$T$8,$B$1:$T$1)*(1+$B$29)^(C31-$B$1))) -> 100.36897 | D38: =(SUM('M1 Demand Driver'!J8:J16)/SUM('M1 Demand Driver'!J8:J17)*MAX(0,_xlfn.FORECAST.LINEAR(D31,$B$8:$T$8,$B$1:$T$1)))+('M1 Demand Driver'!J17/SUM('M1 Demand Driver'!J8:J17)*MAX(0,_xlfn.FORECAST.LINEAR(D31,$B$8:$T$8,$B$1:$T$1)*(1+$B$29)^(D31-$B$1))) -> 99.480046 | E38: =(SUM('M1 Demand Driver'!I8:I16)/SUM('M1 Demand Driver'!I8:I17)*MAX(0,_xlfn.FORECAST.LINEAR(E31,$B$8:$T$8,$B$1:$T$1)))+('M1 Demand Driver'!I17/SUM('M1 Demand Driver'!I8:I17)*MAX(0,_xlfn.FORECAST.LINEAR(E31,$B$8:$T$8,$B$1:$T$1)*(1+$B$29)^(E31-$B$1))) -> 98.588335 | F38: =(SUM('M1 Demand Driver'!H8:H16)/SUM('M1 Demand Driver'!H8:H17)*MAX(0,_xlfn.FORECAST.LINEAR(F31,$B$8:$T$8,$B$1:$T$1)))+('M1 Demand Driver'!H17/SUM('M1 Demand Driver'!H8:H17)*MAX(0,_xlfn.FORECAST.LINEAR(F31,$B$8:$T$8,$B$1:$T$1)*(1+$B$29)^(F31-$B$1))) -> 97.693995 | G38: =(SUM('M1 Demand Driver'!G8:G16)/SUM('M1 Demand Driver'!G8:G17)*MAX(0,_xlfn.FORECAST.LINEAR(G31,$B$8:$T$8,$B$1:$T$1)))+('M1 Demand Driver'!G17/SUM('M1 Demand Driver'!G8:G17)*MAX(0,_xlfn.FORECAST.LINEAR(G31,$B$8:$T$8,$B$1:$T$1)*(1+$B$29)^(G31-$B$1))) -> 96.797185 | H38: =(SUM('M1 Demand Driver'!F8:F16)/SUM('M1 Demand Driver'!F8:F17)*MAX(0,_xlfn.FORECAST.LINEAR(H31,$B$8:$T$8,$B$1:$T$1)))+('M1 Demand Driver'!F17/SUM('M1 Demand Driver'!F8:F17)*MAX(0,_xlfn.FORECAST.LINEAR(H31,$B$8:$T$8,$B$1:$T$1)*(1+$B$29)^(H31-$B$1))) -> 95.898064 | I38: =(SUM('M1 Demand Driver'!E8:E16)/SUM('M1 Demand Driver'!E8:E17)*MAX(0,_xlfn.FORECAST.LINEAR(I31,$B$8:$T$8,$B$1:$T$1)))+('M1 Demand Driver'!E17/SUM('M1 Demand Driver'!E8:E17)*MAX(0,_xlfn.FORECAST.LINEAR(I31,$B$8:$T$8,$B$1:$T$1)*(1+$B$29)^(I31-$B$1))) -> 94.996798 | J38: =(SUM('M1 Demand Driver'!D8:D16)/SUM('M1 Demand Driver'!D8:D17)*MAX(0,_xlfn.FORECAST.LINEAR(J31,$B$8:$T$8,$B$1:$T$1)))+('M1 Demand Driver'!D17/SUM('M1 Demand Driver'!D8:D17)*MAX(0,_xlfn.FORECAST.LINEAR(J31,$B$8:$T$8,$B$1:$T$1)*(1+$B$29)^(J31-$B$1))) -> 94.093583 | K38: =(SUM('M1 Demand Driver'!C8:C16)/SUM('M1 Demand Driver'!C8:C17)*MAX(0,_xlfn.FORECAST.LINEAR(K31,$B$8:$T$8,$B$1:$T$1)))+('M1 Demand Driver'!C17/SUM('M1 Demand Driver'!C8:C17)*MAX(0,_xlfn.FORECAST.LINEAR(K31,$B$8:$T$8,$B$1:$T$1)*(1+$B$29)^(K31-$B$1))) -> 93.188691 | L38: =(SUM('M1 Demand Driver'!B8:B16)/SUM('M1 Demand Driver'!B8:B17)*MAX(0,_xlfn.FORECAST.LINEAR(L31,$B$8:$T$8,$B$1:$T$1)))+('M1 Demand Driver'!B17/SUM('M1 Demand Driver'!B8:B17)*MAX(0,_xlfn.FORECAST.LINEAR(L31,$B$8:$T$8,$B$1:$T$1)*(1+$B$29)^(L31-$B$1))) -> 92.282535
A39: 65 Years Old & Above | B39: =MAX(0,_xlfn.FORECAST.LINEAR(B31, $B$9:$T$9, $B$1:$T$1)*(1+$B$29)^(B31-$B$1)) -> 289.21351 | C39: =MAX(0,_xlfn.FORECAST.LINEAR(C31, $B$9:$T$9, $B$1:$T$1)*(1+$B$29)^(C31-$B$1)) -> 290.59617 | D39: =MAX(0,_xlfn.FORECAST.LINEAR(D31, $B$9:$T$9, $B$1:$T$1)*(1+$B$29)^(D31-$B$1)) -> 291.98499 | E39: =MAX(0,_xlfn.FORECAST.LINEAR(E31, $B$9:$T$9, $B$1:$T$1)*(1+$B$29)^(E31-$B$1)) -> 293.37998 | F39: =MAX(0,_xlfn.FORECAST.LINEAR(F31, $B$9:$T$9, $B$1:$T$1)*(1+$B$29)^(F31-$B$1)) -> 294.78118 | G39: =MAX(0,_xlfn.FORECAST.LINEAR(G31, $B$9:$T$9, $B$1:$T$1)*(1+$B$29)^(G31-$B$1)) -> 296.18861 | H39: =MAX(0,_xlfn.FORECAST.LINEAR(H31, $B$9:$T$9, $B$1:$T$1)*(1+$B$29)^(H31-$B$1)) -> 297.60228 | I39: =MAX(0,_xlfn.FORECAST.LINEAR(I31, $B$9:$T$9, $B$1:$T$1)*(1+$B$29)^(I31-$B$1)) -> 299.02223 | ... L39: =MAX(0,_xlfn.FORECAST.LINEAR(L31, $B$9:$T$9, $B$1:$T$1)*(1+$B$29)^(L31-$B$1)) -> 303.31997
A40: Total Acute Hospitals - Projected
A41: 0 - 14 Years Old (Projected) | B41: =B33+B37 -> 328.69123 | C41: =C33+C37 -> 323.68298 | D41: =D33+D37 -> 318.67474 | E41: =E33+E37 -> 313.66649 | F41: =F33+F37 -> 308.65825 | G41: =G33+G37 -> 303.65 | H41: =H33+H37 -> 298.64175 | I41: =I33+I37 -> 293.63351 | ... L41: =L33+L37 -> 278.60877 | M41: =B3+B7 -> 254.9
A42: 15 - 64 Years Old (Projected) | B42: =B34+B38 -> 202.65274 | C42: =C34+C38 -> 200.4397 | D42: =D34+D38 -> 198.22017 | E42: =E34+E38 -> 195.99447 | F42: =F34+F38 -> 193.76292 | G42: =G34+G38 -> 191.52587 | H42: =H34+H38 -> 189.28365 | I42: =I34+I38 -> 187.03659 | ... L42: =L34+L38 -> 180.27127 | M42: =B4+B8 -> 168.8
A43: 65 Years Old & Above (Projected) | B43: =B35+B39 -> 657.57839 | C43: =C35+C39 -> 659.2183 | D43: =D35+D39 -> 660.85405 | E43: =E35+E39 -> 662.48553 | F43: =F35+F39 -> 664.11263 | G43: =G35+G39 -> 665.73523 | H43: =H35+H39 -> 667.35322 | I43: =I35+I39 -> 668.96649 | ... L43: =L35+L39 -> 673.7768 | M43: =B5+B9 -> 671.3
A44: Admission Rate - Total
A45: 0 - 14 Years Old | B45: =AVERAGE(B33,B37)/1000 -> 0.16434561 | C45: =AVERAGE(C33,C37)/1000 -> 0.16184149 | D45: =AVERAGE(D33,D37)/1000 -> 0.15933737 | E45: =AVERAGE(E33,E37)/1000 -> 0.15683325 | F45: =AVERAGE(F33,F37)/1000 -> 0.15432912 | G45: =AVERAGE(G33,G37)/1000 -> 0.151825 | H45: =AVERAGE(H33,H37)/1000 -> 0.14932088 | I45: =AVERAGE(I33,I37)/1000 -> 0.14681675 | ... L45: =AVERAGE(L33,L37)/1000 -> 0.13930439
A46: 15 - 64 Years Old | B46: =AVERAGE(B34,B38)/1000 -> 0.10132637 | C46: =AVERAGE(C34,C38)/1000 -> 0.10021985 | D46: =AVERAGE(D34,D38)/1000 -> 0.099110086 | E46: =AVERAGE(E34,E38)/1000 -> 0.097997234 | F46: =AVERAGE(F34,F38)/1000 -> 0.096881462 | G46: =AVERAGE(G34,G38)/1000 -> 0.095762937 | H46: =AVERAGE(H34,H38)/1000 -> 0.094641825 | I46: =AVERAGE(I34,I38)/1000 -> 0.093518297 | ... L46: =AVERAGE(L34,L38)/1000 -> 0.090135634
...

Sheet M2 Beds
A1: Beds In Inpatient Facilities | B1: 2023 | C1: 2022 | D1: 2021 | E1: 2020 | F1: 2019 | G1: 2018 | H1: 2017 | I1: 2016 | J1: 2015 | K1: 2014 | L1: 2013 | M1: 2012 | N1: 2011 | O1: 2010 | P1: 2009 | Q1: 2008 | R1: 2007 | S1: 2006
A2: Acute Hospitals | B2: 12025 | C2: 11830 | D2: 11704 | E2: 11545 | F2: 11321 | G2: 10826 | H2: 10340 | I2: 10318 | J2: 9844 | K2: 9262 | L2: 8939 | M2: 8725 | N2: 8304 | O2: 8249 | P2: 8289 | Q2: 8190 | R2: 8235 | S2: 8187
A3: Public | B3: 9956 | C3: 9820 | D3: 9762 | E3: 9610 | F3: 9404 | G3: 9071 | H3: 8623 | I3: 8561 | J3: 8128 | K3: 7652 | L3: 7377 | M3: 7170 | N3: 6925 | O3: 6871 | P3: 6416 | Q3: 6255 | R3: 6304 | S3: 6256
A4: Not-For-Profit | B4: 347 | C4: 273 | D4: 270 | E4: 285 | F4: 288 | G4: 273 | H4: 271 | I4: 316 | J4: 316 | K4: 283 | L4: 283 | M4: 283 | N4: 283 | O4: 283 | P4: 303 | Q4: 303 | R4: 303 | S4: 303
A5: Private | B5: 1722 | C5: 1737 | D5: 1672 | E5: 1650 | F5: 1629 | G5: 1482 | H5: 1446 | I5: 1441 | J5: 1400 | K5: 1327 | L5: 1279 | M5: 1272 | N5: 1096 | O5: 1095 | P5: 1570 | Q5: 1632 | R5: 1628 | S5: 1628
A6: Psychiatric Hospitals | B6: 1950 | C6: 1950 | D6: 1950 | E6: 1950 | F6: 1950 | G6: 1950 | H6: 1950 | I6: 1950 | J6: 1950 | K6: 1950 | L6: 2010 | M6: 2010 | N6: 2010 | O6: 2010 | P6: 2040 | Q6: 2064 | R6: 2064 | S6: 2113
A7: Public | B7: 1950 | C7: 1950 | D7: 1950 | E7: 1950 | F7: 1950 | G7: 1950 | H7: 1950 | I7: 1950 | J7: 1950 | K7: 1950 | L7: 2010 | M7: 2010 | N7: 2010 | O7: 2010 | P7: 2040 | Q7: 2064 | R7: 2064 | S7: 2064
A8: Not-For-Profit | B8: 0 | C8: 0 | D8: 0 | E8: 0 | F8: 0 | G8: 0 | H8: 0 | I8: 0 | J8: 0 | K8: 0 | L8: 0 | M8: 0 | N8: 0 | O8: 0 | P8: 0 | Q8: 0 | R8: 0 | S8: 0
A9: Private | B9: 0 | C9: 0 | D9: 0 | E9: 0 | F9: 0 | G9: 0 | H9: 0 | I9: 0 | J9: 0 | K9: 0 | L9: 0 | M9: 0 | N9: 0 | O9: 0 | P9: 0 | Q9: 0 | R9: 0 | S9: 49
A10: Community Hospitals | B10: 2303 | C10: 2194 | D10: 2011 | E10: 2069 | F10: 1986 | G10: 1778 | H10: 1663 | I10: 1663 | J10: 1464 | K10: 1065 | L10: 852 | M10: 842 | N10: 800 | O10: 842 | P10: 877 | Q10: 872 | R10: 749 | S10: 771
A11: Public | B11: 1331 | C11: 1226 | D11: 1112 | E11: 1130 | F11: 974 | G11: 799 | H11: 690 | I11: 690 | J11: 503 | K11: 142 | L11: 110 | M11: 100 | N11: 100 | O11: 0 | P11: 0 | Q11: 0 | R11: 0 | S11: 0
A12: Not-For-Profit | B12: 972 | C12: 968 | D12: 899 | E12: 939 | F12: 1012 | G12: 979 | H12: 969 | I12: 961 | J12: 961 | K12: 905 | L12: 722 | M12: 722 | N12: 680 | O12: 818 | P12: 819 | Q12: 814 | R12: 691 | S12: 713
... A17: Private | B17: 4474 | C17: 3932 | D17: 3905 | E17: 3867 | F17: 3858 | G17: 3671 | H17: 3765 | I17: 3854 | J17: 3895 | K17: 3575 | L17: 3684 | M17: 3400 | N17: 3303 | O17: 3258 | P17: 3180 | Q17: 3657 | R17: 3504 | S17: 3282
A18: Inpatient Hospice Palliative Care Service (IHPCS) | B18: 284 | C18: 264 | D18: 264 | E18: 253 | F18: na | G18: na | H18: na | I18: na | J18: na | K18: na | L18: na | M18: na | N18: na | O18: na | P18: na | Q18: na | R18: na | S18: na
A19: Public | B19: 64 | C19: 64 | D19: 64 | E19: 60 | F19: na | G19: na | H19: na | I19: na | J19: na | K19: na | L19: na | M19: na | N19: na | O19: na | P19: na | Q19: na | R19: na | S19: na
A20: Not-For-Profit | B20: 220 | C20: 200 | D20: 200 | E20: 193 | F20: na | G20: na | H20: na | I20: na | J20: na | K20: na | L20: na | M20: na | N20: na | O20: na | P20: na | Q20: na | R20: na | S20: na
A21: Private | B21: 0 | C21: 0 | D21: 0 | E21: 0 | F21: na | G21: na | H21: na | I21: na | J21: na | K21: na | L21: na | M21: na | N21: na | O21: na | P21: na | Q21: na | R21: na | S21: na
A23: Projected Beds
A24: Annual Bed Expansion Rate (r) | B24: ='M2 BOR & Tradeoff analysis'!B9 -> 0.0353
B25: Projected | M25: Historical
A26: Beds In Inpatient Facilities | B26: 2035 | C26: =B26-1 -> 2034 | D26: =C26-1 -> 2033 | E26: =D26-1 -> 2032 | F26: =E26-1 -> 2031 | G26: =F26-1 -> 2030 | H26: =G26-1 -> 2029 | I26: =H26-1 -> 2028 | J26: =I26-1 -> 2027 | ... L26: =K26-1 -> 2025 | M26: 2024 | N26: 2023 | O26: 2022 | P26: 2021 | Q26: 2020 | R26: 2019 | S26: 2018 | T26: 2017 | U26: 2016 | V26: 2015 | W26: 2014 | X26: 2013 | Y26: 2012 | Z26: 2011 | AA26: 2010 | AB26: 2009 | AC26: 2008 | AD26: 2007 | AE26: 2006
A27: Public Acute Hospitals - by History | B27: =MAX(0, _xlfn.FORECAST.LINEAR(B26, $B$3:$S$3,$B$1:$S$1)*(1+$B$24)^(B26-2024)) -> 19336.378 | C27: =MAX(0, _xlfn.FORECAST.LINEAR(C26, $B$3:$S$3,$B$1:$S$1)*(1+$B$24)^(C26-2024)) -> 18318.693 | D27: =MAX(0, _xlfn.FORECAST.LINEAR(D26, $B$3:$S$3,$B$1:$S$1)*(1+$B$24)^(D26-2024)) -> 17347.927 | E27: =MAX(0, _xlfn.FORECAST.LINEAR(E26, $B$3:$S$3,$B$1:$S$1)*(1+$B$24)^(E26-2024)) -> 16422.063 | F27: =MAX(0, _xlfn.FORECAST.LINEAR(F26, $B$3:$S$3,$B$1:$S$1)*(1+$B$24)^(F26-2024)) -> 15539.168 | G27: =MAX(0, _xlfn.FORECAST.LINEAR(G26, $B$3:$S$3,$B$1:$S$1)*(1+$B$24)^(G26-2024)) -> 14697.389 | H27: =MAX(0, _xlfn.FORECAST.LINEAR(H26, $B$3:$S$3,$B$1:$S$1)*(1+$B$24)^(H26-2024)) -> 13894.948 | I27: =MAX(0, _xlfn.FORECAST.LINEAR(I26, $B$3:$S$3,$B$1:$S$1)*(1+$B$24)^(I26-2024)) -> 13130.141 | ... M27: =MAX(0, _xlfn.FORECAST.LINEAR(M26, $B$3:$S$3,$B$1:$S$1)*(1+$B$24)^(M26-2024)) -> 10415.582 | N27: =B3 -> 9956
A28: Public Acute Hospitals - by Exp. Rate | B28: =ROUNDUP(C28*(1+$B$24),0) -> 17583 | C28: =ROUNDUP(D28*(1+$B$24),0) -> 16983 | D28: =ROUNDUP(E28*(1+$B$24),0) -> 16403 | E28: =ROUNDUP(F28*(1+$B$24),0) -> 15843 | F28: =ROUNDUP(G28*(1+$B$24),0) -> 15302 | G28: =ROUNDUP(H28*(1+$B$24),0) -> 14780 | H28: =ROUNDUP(I28*(1+$B$24),0) -> 14276 | I28: =ROUNDUP(J28*(1+$B$24),0) -> 13789 | ... L28: =ROUNDUP(M28*(1+$B$24),0) -> 12424 | M28: ='M2 BOR & Tradeoff analysis'!B7 -> 12000 | N28: =B3 -> 9956
A29: Public Acute Hospitals | B29: =B28 -> 17583 | C29: =C28 -> 16983 | D29: =D28 -> 16403 | E29: =E28 -> 15843 | F29: =F28 -> 15302 | G29: =G28 -> 14780 | H29: =H28 -> 14276 | I29: =I28 -> 13789 | ... M29: =M28 -> 12000 | N29: 9956 | O29: 9820 | P29: 9762 | Q29: 9610 | R29: 9404 | S29: 9071 | T29: 8623 | U29: 8561 | V29: 8128 | W29: 7652 | X29: 7377 | Y29: 7170 | Z29: 6925 | AA29: 6871 | AB29: 6416 | AC29: 6255 | AD29: 6304 | AE29: 6256
A30: Public Acute Hospitals - History | N30: 9956 | O30: 9820 | P30: 9762 | Q30: 9610 | R30: 9404 | S30: 9071 | T30: 8623 | U30: 8561 | V30: 8128 | W30: 7652 | X30: 7377 | Y30: 7170 | Z30: 6925 | AA30: 6871 | AB30: 6416 | AC30: 6255 | AD30: 6304 | AE30: 6256
L33: Annual Bed Expansion Rate (r) - Data Source: MOH Bed Expansion Plan
L34: Base beds (2024): B_2024=12,000​ (public acute hospital beds)
L35: Additional beds (2025–2030): 2,800
L36: Target beds (2030): B_2030​=12,000+2,800=14,800
L37: Time period: 6 years (n=6)
L38: B_2030=B_2024*(1+r)^n, r=the annual expansion rate
L39: Solve for r=3.53%
L41: Two methods for predicting the bed number form 2024 to 2035:
L42: A27 'Public Acute Hospitals - by History' uses historical data (2006–2023) to make predictions from 2024 to 2035.
L43: A28 'Acute Hospitals - by Exp. Rate' is calculated using the expansion rate r and the bed number of 2024 (defined in BOR!A7), which is not affected by historical data.
L45: A29 'Public Acute Hospitals' is a complete sequence of bed numbers from 2006 to 2035, combining historical data (2006-2023) and predicted data (2024-2035).
